Workbook

Sheet Sheet1
D1: Ramadan 2025
C3: MUTTON SAVAN | E3: CHICKEN SAVAN
A4: Order No: | B4: Name | C4: Full M/Savan | D4: Half M/Savan | E4: Full C/Svan | F4: Half C/Savan | G4: Extra Chicken | H4: Extra Wattalpam | I4: Number | J4: Extra Notes | K4: Total | L4: Payment Status
A5: 7 | B5: Ramzy | E5: 1 | I5: 7546778168 | K5: =Table1[[#This Row],[Full M/Savan]]*$O$11+Table1[[#This Row],[Half M/Savan]]*$P$11+Table1[[#This Row],[Extra Chicken]]*$Q$11+Table1[[#This Row],[Extra Wattalpam]]*$R$11+Table1[[#This Row],[Full C/Svan]]*$O$11+Table1[[#This Row],[Half C/Savan]]*$P$11 -> 89 | L5: Paid
A6: 5 | B6: Najahaasan | E6: 1 | I6: 7306069201 | K6: =Table1[[#This Row],[Full M/Savan]]*$O$11+Table1[[#This Row],[Half M/Savan]]*$P$11+Table1[[#This Row],[Extra Chicken]]*$Q$11+Table1[[#This Row],[Extra Wattalpam]]*$R$11+Table1[[#This Row],[Full C/Svan]]*$O$11+Table1[[#This Row],[Half C/Savan]]*$P$11 -> 89 | L6: Paid
A7: 6 | B7: Asdam | C7: 1 | I7: 7503224216 | J7: 2pm | K7: =Table1[[#This Row],[Full M/Savan]]*$O$11+Table1[[#This Row],[Half M/Savan]]*$P$11+Table1[[#This Row],[Extra Chicken]]*$Q$11+Table1[[#This Row],[Extra Wattalpam]]*$R$11+Table1[[#This Row],[Full C/Svan]]*$O$11+Table1[[#This Row],[Half C/Savan]]*$P$11 -> 89 | L7: Paid
A8: 25 | B8: IRFAN | D8: 1 | I8: 7910394346 | K8: =Table1[[#This Row],[Full M/Savan]]*$O$11+Table1[[#This Row],[Half M/Savan]]*$P$11+Table1[[#This Row],[Extra Chicken]]*$Q$11+Table1[[#This Row],[Extra Wattalpam]]*$R$11+Table1[[#This Row],[Full C/Svan]]*$O$11+Table1[[#This Row],[Half C/Savan]]*$P$11 -> 48 | L8: Paid
A9: =A8+1 -> 26 | B9: Shuhama Abdul Kadir | C9: 1 | I9: 07913902535 | K9: =Table1[[#This Row],[Full M/Savan]]*$O$11+Table1[[#This Row],[Half M/Savan]]*$P$11+Table1[[#This Row],[Extra Chicken]]*$Q$11+Table1[[#This Row],[Extra Wattalpam]]*$R$11+Table1[[#This Row],[Full C/Svan]]*$O$11+Table1[[#This Row],[Half C/Savan]]*$P$11 -> 89 | L9: Paid | N9: Cost | O9: Full Savan | P9: Half Savan | Q9: Chicken | R9: Wattalapam | S9: Massi Sambal/Green Peas
A10: =A9+1 -> 27 | B10: Fathima | C10: 1 | I10: 07429959249 | K10: =Table1[[#This Row],[Full M/Savan]]*$O$11+Table1[[#This Row],[Half M/Savan]]*$P$11+Table1[[#This Row],[Extra Chicken]]*$Q$11+Table1[[#This Row],[Extra Wattalpam]]*$R$11+Table1[[#This Row],[Full C/Svan]]*$O$11+Table1[[#This Row],[Half C/Savan]]*$P$11 -> 89 | L10: Paid
A11: =A10+1 -> 28 | B11: DELIVERY | C11: 1 | G11: 2 | J11: ASK ABOUT WHAT IT SAYS IN THE NOTES | K11: =Table1[[#This Row],[Full M/Savan]]*$O$11+Table1[[#This Row],[Half M/Savan]]*$P$11+Table1[[#This Row],[Extra Chicken]]*$Q$11+Table1[[#This Row],[Extra Wattalpam]]*$R$11+Table1[[#This Row],[Full C/Svan]]*$O$11+Table1[[#This Row],[Half C/Savan]]*$P$11 -> 121 | L11: Paid | M11: DELIEVERY PAY LATER | O11: 89 | P11: 48 | Q11: 16 | R11: 16 | S11: 6
A12: =A11+1 -> 29 | B12: Firoza | C12: 2 | G12: 2 | I12: 7986542700 | J12: W/C separate | K12: =Table1[[#This Row],[Full M/Savan]]*$O$11+Table1[[#This Row],[Half M/Savan]]*$P$11+Table1[[#This Row],[Extra Chicken]]*$Q$11+Table1[[#This Row],[Extra Wattalpam]]*$R$11+Table1[[#This Row],[Full C/Svan]]*$O$11+Table1[[#This Row],[Half C/Savan]]*$P$11 -> 210 | L12: Paid | M12: BANK TRANSFER
A13: =A12+1 -> 30 | B13: Imtiaz | C13: 1 | D13: 1 | G13: 1.5 | I13: 07894951535 | K13: =Table1[[#This Row],[Full M/Savan]]*$O$11+Table1[[#This Row],[Half M/Savan]]*$P$11+Table1[[#This Row],[Extra Chicken]]*$Q$11+Table1[[#This Row],[Extra Wattalpam]]*$R$11+Table1[[#This Row],[Full C/Svan]]*$O$11+Table1[[#This Row],[Half C/Savan]]*$P$11 -> 161 | L13: Paid | N13: Total | S13: Chicken Biryani
A14: =A13+1 -> 31 | B14: Nawas upstairs | D14: 2 | G14: 1 | I14: 07983537012 | K14: =Table1[[#This Row],[Full M/Savan]]*$O$11+Table1[[#This Row],[Half M/Savan]]*$P$11+Table1[[#This Row],[Extra Chicken]]*$Q$11+Table1[[#This Row],[Extra Wattalpam]]*$R$11+Table1[[#This Row],[Full C/Svan]]*$O$11+Table1[[#This Row],[Half C/Savan]]*$P$11 -> 112 | L14: Paid | M14: - | O14: =C119 -> 60 | P14: =D119 -> 41 | Q14: =C119+(D119/2)+G119+(E119*2)+F119 -> 120.5 | R14: =C119+(D119/2)+H119 -> 87.5
A15: =A14+1 -> 32 | B15: Ruzad | D15: 1 | I15: 07916138595 | K15: =Table1[[#This Row],[Full M/Savan]]*$O$11+Table1[[#This Row],[Half M/Savan]]*$P$11+Table1[[#This Row],[Extra Chicken]]*$Q$11+Table1[[#This Row],[Extra Wattalpam]]*$R$11+Table1[[#This Row],[Full C/Svan]]*$O$11+Table1[[#This Row],[Half C/Savan]]*$P$11 -> 48 | L15: Paid
A16: =A15+1 -> 33 | B16: Ithabith Naja | C16: 3 | G16: 3 | I16: 07789914912 | K16: =Table1[[#This Row],[Full M/Savan]]*$O$11+Table1[[#This Row],[Half M/Savan]]*$P$11+Table1[[#This Row],[Extra Chicken]]*$Q$11+Table1[[#This Row],[Extra Wattalpam]]*$R$11+Table1[[#This Row],[Full C/Svan]]*$O$11+Table1[[#This Row],[Half C/Savan]]*$P$11 -> 315 | L16: Paid
A17: =A16+1 -> 34 | B17: Samith | C17: 1 | G17: 1 | I17: 07794461409 | K17: =Table1[[#This Row],[Full M/Savan]]*$O$11+Table1[[#This Row],[Half M/Savan]]*$P$11+Table1[[#This Row],[Extra Chicken]]*$Q$11+Table1[[#This Row],[Extra Wattalpam]]*$R$11 -> 105 | L17: Paid | M17: bank transfer
A18: =A17+1 -> 35 | B18: Faizal | C18: 1 | I18: 07801512520 | K18: =Table1[[#This Row],[Full M/Savan]]*$O$11+Table1[[#This Row],[Half M/Savan]]*$P$11+Table1[[#This Row],[Extra Chicken]]*$Q$11+Table1[[#This Row],[Extra Wattalpam]]*$R$11 -> 89 | L18: Paid
A19: =A18+1 -> 36 | B19: Shanas | C19: 1 | H19: 1 | I19: 07894278301 | K19: =Table1[[#This Row],[Full M/Savan]]*$O$11+Table1[[#This Row],[Half M/Savan]]*$P$11+Table1[[#This Row],[Extra Chicken]]*$Q$11+Table1[[#This Row],[Extra Wattalpam]]*$R$11 -> 105 | L19: Paid
A20: =A19+1 -> 37 | B20: Faizool Mosthofa | C20: 1 | I20: 07920425804 | K20: =Table1[[#This Row],[Full M/Savan]]*$O$11+Table1[[#This Row],[Half M/Savan]]*$P$11+Table1[[#This Row],[Extra Chicken]]*$Q$11+Table1[[#This Row],[Extra Wattalpam]]*$R$11 -> 89 | L20: Paid
A21: =A20+1 -> 38 | B21: Lahir | G21: 3 | I21: 07545909193 | K21: =Table1[[#This Row],[Full M/Savan]]*$O$11+Table1[[#This Row],[Half M/Savan]]*$P$11+Table1[[#This Row],[Extra Chicken]]*$Q$11+Table1[[#This Row],[Extra Wattalpam]]*$R$11 -> 48 | L21: Paid
A22: =A21+1 -> 39 | B22: Ramees | C22: 1 | K22: =Table1[[#This Row],[Full M/Savan]]*$O$11+Table1[[#This Row],[Half M/Savan]]*$P$11+Table1[[#This Row],[Extra Chicken]]*$Q$11+Table1[[#This Row],[Extra Wattalpam]]*$R$11 -> 89 | L22: Paid | M22: 1023 taken for y days meal
A23: =A22+1 -> 40 | B23: Shyam Watford | C23: 1 | D23: 1 | G23: 1.5 | I23: 7850523528 | K23: =Table1[[#This Row],[Full M/Savan]]*$O$11+Table1[[#This Row],[Half M/Savan]]*$P$11+Table1[[#This Row],[Extra Chicken]]*$Q$11+Table1[[#This Row],[Extra Wattalpam]]*$R$11 -> 161 | L23: Paid
A24: =A23+1 -> 41 | B24: Nawas Nawaz | D24: 1 | I24: 07869826665 | K24: =Table1[[#This Row],[Full M/Savan]]*$O$11+Table1[[#This Row],[Half M/Savan]]*$P$11+Table1[[#This Row],[Extra Chicken]]*$Q$11+Table1[[#This Row],[Extra Wattalpam]]*$R$11 -> 48 | L24: Paid
A25: =A24+1 -> 42 | B25: Theva | D25: 1 | I25: 07484860085 | K25: =Table1[[#This Row],[Full M/Savan]]*$O$11+Table1[[#This Row],[Half M/Savan]]*$P$11+Table1[[#This Row],[Extra Chicken]]*$Q$11+Table1[[#This Row],[Extra Wattalpam]]*$R$11 -> 48 | L25: Paid
A26: =A25+1 -> 43 | B26: Zarook | C26: 1 | D26: 1 | I26: 07788368448 | K26: =Table1[[#This Row],[Full M/Savan]]*$O$11+Table1[[#This Row],[Half M/Savan]]*$P$11+Table1[[#This Row],[Extra Chicken]]*$Q$11+Table1[[#This Row],[Extra Wattalpam]]*$R$11 -> 137 | L26: Paid
A27: =A26+1 -> 44 | B27: Aslam | C27: 1 | I27: 07596895705 | K27: =Table1[[#This Row],[Full M/Savan]]*$O$11+Table1[[#This Row],[Half M/Savan]]*$P$11+Table1[[#This Row],[Extra Chicken]]*$Q$11+Table1[[#This Row],[Extra Wattalpam]]*$R$11 -> 89 | L27: Paid | M27: PAY LATER TAKEN SAHAN regular CUSTOMER
A28: =A27+1 -> 45 | B28: Marithar | C28: 2 | G28: 2 | I28: 07718928344 | K28: =Table1[[#This Row],[Full M/Savan]]*$O$11+Table1[[#This Row],[Half M/Savan]]*$P$11+Table1[[#This Row],[Extra Chicken]]*$Q$11+Table1[[#This Row],[Extra Wattalpam]]*$R$11 -> 210 | L28: Paid
A29: =A28+1 -> 46 | B29: Ankar | C29: 1 | G29: 2 | I29: 07944145946 | J29: 15 MUTTON ROLLS 1 TEA | K29: =Table1[[#This Row],[Full M/Savan]]*$O$11+Table1[[#This Row],[Half M/Savan]]*$P$11+Table1[[#This Row],[Extra Chicken]]*$Q$11+Table1[[#This Row],[Extra Wattalpam]]*$R$11+15 -> 136 | L29: Paid
A30: =A29+1 -> 47 | B30: Irshad | C30: 1 | I30: 7861612196 | K30: =Table1[[#This Row],[Full M/Savan]]*$O$11+Table1[[#This Row],[Half M/Savan]]*$P$11+Table1[[#This Row],[Extra Chicken]]*$Q$11+Table1[[#This Row],[Extra Wattalpam]]*$R$11 -> 89 | L30: Paid
A31: =A30+1 -> 48 | B31: Nazeem | C31: 1 | I31: 07975743333 | K31: =Table1[[#This Row],[Full M/Savan]]*$O$11+Table1[[#This Row],[Half M/Savan]]*$P$11+Table1[[#This Row],[Extra Chicken]]*$Q$11+Table1[[#This Row],[Extra Wattalpam]]*$R$11 -> 89 | L31: Paid
A32: =A31+1 -> 49 | B32: Inisas | D32: 1 | I32: 07404561488 | K32: =Table1[[#This Row],[Full M/Savan]]*$O$11+Table1[[#This Row],[Half M/Savan]]*$P$11+Table1[[#This Row],[Extra Chicken]]*$Q$11+Table1[[#This Row],[Extra Wattalpam]]*$R$11 -> 48 | L32: Paid
A33: =A32+1 -> 50 | B33: Halima Anti | C33: 1 | G33: 1 | I33: 2084266905 | K33: =Table1[[#This Row],[Full M/Savan]]*$O$11+Table1[[#This Row],[Half M/Savan]]*$P$11+Table1[[#This Row],[Extra Chicken]]*$Q$11+Table1[[#This Row],[Extra Wattalpam]]*$R$11 -> 105 | L33: Paid
A34: =A33+1 -> 51 | B34: Faisal | C34: 1 | G34: 1 | I34: 07956213623 | K34: =Table1[[#This Row],[Full M/Savan]]*$O$11+Table1[[#This Row],[Half M/Savan]]*$P$11+Table1[[#This Row],[Extra Chicken]]*$Q$11+Table1[[#This Row],[Extra Wattalpam]]*$R$11 -> 105 | L34: Paid
A35: =A34+1 -> 52 | B35: Faisal Mosque | C35: 1 | I35: 07397566080 | K35: =Table1[[#This Row],[Full M/Savan]]*$O$11+Table1[[#This Row],[Half M/Savan]]*$P$11+Table1[[#This Row],[Extra Chicken]]*$Q$11+Table1[[#This Row],[Extra Wattalpam]]*$R$11 -> 89 | L35: Paid
A36: =A35+1 -> 53 | B36: Junaideen | C36: 3 | K36: =Table1[[#This Row],[Full M/Savan]]*$O$11+Table1[[#This Row],[Half M/Savan]]*$P$11+Table1[[#This Row],[Extra Chicken]]*$Q$11+Table1[[#This Row],[Extra Wattalpam]]*$R$11 -> 267 | L36: Paid
A37: =A36+1 -> 54 | B37: Bari | C37: 2 | I37: 07747612490 | J37: Dad took £110 from the pot to pay Bari and I got 150 from him | K37: =Table1[[#This Row],[Full M/Savan]]*$O$11+Table1[[#This Row],[Half M/Savan]]*$P$11+Table1[[#This Row],[Extra Chicken]]*$Q$11+Table1[[#This Row],[Extra Wattalpam]]*$R$11 -> 178 | L37: Paid | M37: ?? Pay later
A38: =A37+1 -> 55 | B38: Riza | D38: 2 | G38: 1 | J38: PAY LATER RIZA DELIVERY | K38: =Table1[[#This Row],[Full M/Savan]]*$O$11+Table1[[#This Row],[Half M/Savan]]*$P$11+Table1[[#This Row],[Extra Chicken]]*$Q$11+Table1[[#This Row],[Extra Wattalpam]]*$R$11 -> 112 | L38: Paid | M38: PAY LATER | N38: He paid now at 3pm
A39: =A38+1 -> 56 | B39: Delivery Slough | C39: 3 | D39: 1 | G39: 4 | J39: PAY LATER RIZA DELIVERY | K39: =Table1[[#This Row],[Full M/Savan]]*$O$11+Table1[[#This Row],[Half M/Savan]]*$P$11+Table1[[#This Row],[Extra Chicken]]*$Q$11+Table1[[#This Row],[Extra Wattalpam]]*$R$11 -> 379 | L39: Paid | M39: PAY LATER
A40: =A39+1 -> 57 | B40: Hafeef | C40: 2 | I40: 7792746434 | K40: =Table1[[#This Row],[Full M/Savan]]*$O$11+Table1[[#This Row],[Half M/Savan]]*$P$11+Table1[[#This Row],[Extra Chicken]]*$Q$11+Table1[[#This Row],[Extra Wattalpam]]*$R$11 -> 178 | L40: Paid
A41: =A40+1 -> 58 | B41: Azinar | C41: 1 | D41: 1 | G41: 1 | I41: 7814753999 | K41: =Table1[[#This Row],[Full M/Savan]]*$O$11+Table1[[#This Row],[Half M/Savan]]*$P$11+Table1[[#This Row],[Extra Chicken]]*$Q$11+Table1[[#This Row],[Extra Wattalpam]]*$R$11 -> 153 | L41: Paid
...

Sheet Sheet2
A1: Customer Lookup
A3: Order No: | B3: 25
A5: IF YOU SEARCH BY ORDER NUMBER:
A6: Order No: | B6: Name | C6: Full Savan | D6: Half Savan | E6: Extra Chicken | F6: Extra Wattalapam | G6: Number | H6: Extra Notes | I6: Total | J6: Payment Status
A7: =INDEX(Table1[#All], MATCH($B$3, Table1[[#All],[Order No:]], 0), MATCH(A6, Sheet1!$A$4:$L$4, 0)) -> 25 | B7: =INDEX(Table1[#All], MATCH($B$3, Table1[[#All],[Order No:]], 0), MATCH(B6, Sheet1!$A$4:$L$4, 0)) -> IRFAN | C7: =INDEX(Table1[#All], MATCH($B$3, Table1[[#All],[Order No:]], 0), MATCH(C6, Sheet1!$A$4:$L$4, 0)) -> #N/A | D7: =INDEX(Table1[#All], MATCH($B$3, Table1[[#All],[Order No:]], 0), MATCH(D6, Sheet1!$A$4:$L$4, 0)) -> #N/A | E7: =INDEX(Table1[#All], MATCH($B$3, Table1[[#All],[Order No:]], 0), MATCH(E6, Sheet1!$A$4:$L$4, 0)) -> 0 | F7: =INDEX(Table1[#All], MATCH($B$3, Table1[[#All],[Order No:]], 0), MATCH(F6, Sheet1!$A$4:$L$4, 0)) -> #N/A | G7: =INDEX(Table1[#All], MATCH($B$3, Table1[[#All],[Order No:]], 0), MATCH(G6, Sheet1!$A$4:$L$4, 0)) -> 7910394346 | H7: =INDEX(Table1[#All], MATCH($B$3, Table1[[#All],[Order No:]], 0), MATCH(H6, Sheet1!$A$4:$L$4, 0)) -> 0 | ... J7: =INDEX(Table1[#All], MATCH($B$3, Table1[[#All],[Order No:]], 0), MATCH(J6, Sheet1!$A$4:$L$4, 0)) -> Paid
A10: Number: | B10: 7427147759 | F10: =MATCH($B$3, Table1[[#All],[Order No:]], 0) -> 5 | G10: =MATCH(F6, Sheet1!$A$4:$L$4, 0) -> #N/A
A12: IF YOU SEARCH BY MOBILE NUMBER:
A13: Order No: | B13: Name | C13: Full Savan | D13: Half Savan | E13: Extra Chicken | F13: Extra Wattalapam | G13: Number | H13: Extra Notes | I13: Total | J13: Payment Status
A14: =INDEX(Table1[#All], MATCH($B$10,Table1[[#All],[Number]], 0), MATCH(A6, Sheet1!$A$4:$L$4, 0)) -> #N/A | B14: =INDEX(Table1[#All], MATCH($B$10,Table1[[#All],[Number]], 0), MATCH(B6, Sheet1!$A$4:$L$4, 0)) -> #N/A | C14: =INDEX(Table1[#All], MATCH($B$10,Table1[[#All],[Number]], 0), MATCH(C6, Sheet1!$A$4:$L$4, 0)) -> #N/A | D14: =INDEX(Table1[#All], MATCH($B$10,Table1[[#All],[Number]], 0), MATCH(D6, Sheet1!$A$4:$L$4, 0)) -> #N/A | E14: =INDEX(Table1[#All], MATCH($B$10,Table1[[#All],[Number]], 0), MATCH(E6, Sheet1!$A$4:$L$4, 0)) -> #N/A | G14: =INDEX(Table1[#All], MATCH($B$10,Table1[[#All],[Number]], 0), MATCH(G6, Sheet1!$A$4:$L$4, 0)) -> #N/A | H14: =INDEX(Table1[#All], MATCH($B$10,Table1[[#All],[Number]], 0), MATCH(H6, Sheet1!$A$4:$L$4, 0)) -> #N/A | I14: =INDEX(Table1[#All], MATCH($B$10,Table1[[#All],[Number]], 0), MATCH(I6, Sheet1!$A$4:$L$4, 0)) -> #N/A | J14: =INDEX(Table1[#All], MATCH($B$10,Table1[[#All],[Number]], 0), MATCH(J6, Sheet1!$A$4:$L$4, 0)) -> #N/A
B18: =MATCH($B$10,Table1[[#All],[Number]], 0) -> #N/A
B19: =MATCH(B6, Sheet1!$A$4:$L$4, 0) -> 2
J20: =INDEX(Sheet1!$A$4:$L$103, MATCH($B$10, Table1[[#All],[Number]], 0), MATCH(J6, Sheet1!$A$4:$L$4, 0)) -> #N/A
B23: =MATCH($B$3, Table1[[#All],[Order No:]], 0) -> 5 | C23: =MATCH(B6, Sheet1!$A$4:$L$4, 0) -> 2
B27: =MATCH($B$3,Sheet1!A4:A118, 0) -> 5
B28: =MATCH($B$3, Table1[[#All],[Order No:]], 0) -> 5
